Workbook

Sheet Info_schedule
B12: Corso | C12: A05003 Corporate finance e M&A
B13: Matricola | C13: 34226
B14: Nome | C14: BRYAN
B15: Cognome | C15: LATTUADA
B16: Assigment_n | C16: 5*

Sheet 3_Statements_Model
E4: Histotical data | J4: Forecast Periods
B5: Voce (€ milioni) | C5: 2021 | D5: 2022 | E5: 2023 | F5: 2024 | G5: 2025 | H5: =+G5+1 -> 2026 | I5: =+H5+1 -> 2027 | J5: =+I5+1 -> 2028 | K5: =+J5+1 -> 2029 | L5: =+K5+1 -> 2030
A7: x | B7: Assumptions | O7: x | P7: Data Visualitation
B9: Ricavi | C9: - | D9: - | E9: - | F9: - | G9: - | H9: 0.1 | I9: =+H9+$M$9 -> 0.09 | J9: =+I9+$M$9 -> 0.08 | K9: =+J9+$M$9 -> 0.07 | L9: =+K9+$M$9 -> 0.06 | M9: -0.01 | P9: Y | Q9: 2021 | R9: =+Q9+1 -> 2022 | S9: =+R9+1 -> 2023 | T9: =+S9+1 -> 2024 | U9: =+T9+1 -> 2025 | V9: =+U9+1 -> 2026 | W9: =+V9+1 -> 2027 | X9: =+W9+1 -> 2028 | Y9: =+X9+1 -> 2029 | Z9: =+Y9+1 -> 2030
B10: COGS | C10: - | D10: - | E10: - | F10: - | G10: - | H10: 0.26 | I10: =26%+$M$10 -> 0.26 | J10: =26%+$M$10 -> 0.26 | K10: =26%+$M$10 -> 0.26 | L10: =26%+$M$10 -> 0.26 | P10: Ricavi (Revenues) | Q10: 100 | R10: 115 | S10: 130 | T10: 145 | U10: 160 | V10: =+H28 -> 176 | W10: =+I28 -> 191.84 | X10: =+J28 -> 207.1872 | Y10: =+K28 -> 221.6903 | Z10: =+L28 -> 234.99172
B11: SG&A | C11: - | D11: - | E11: - | F11: - | G11: - | H11: 0.35 | I11: 0.345 | J11: 0.34 | K11: 0.34 | L11: 0.34 | P11: % Gross Profit | Q11: =+C30/C28 -> 0.7 | R11: =+D30/D28 -> 0.70956522 | S11: =+E30/E28 -> 0.72 | T11: =+F30/F28 -> 0.72965517 | U11: =+G30/G28 -> 0.74 | V11: =+H30/H28 -> 0.74 | W11: =+I30/I28 -> 0.74 | X11: =+J30/J28 -> 0.74 | ... Z11: =+L30/L28 -> 0.74
B12: D&A | C12: - | D12: - | E12: - | F12: - | G12: - | H12: 0.85 | I12: 0.85 | J12: 0.85 | K12: 0.85 | L12: 0.85
B13: Tax Rate | C13: - | D13: - | E13: - | F13: - | G13: - | H13: 0.25 | I13: 0.25 | J13: 0.25 | K13: 0.25 | L13: 0.25
C14: - | D14: - | E14: - | F14: - | G14: -
B15: Days Sales Outstanding (DSO) | C15: - | D15: - | E15: - | F15: - | G15: - | H15: 36.5 | I15: 36.5 | J15: 36.5 | K15: 36.5 | L15: 36.5
B16: Days Inventory Outstanding (DIO) | C16: - | D16: - | E16: - | F16: - | G16: - | H16: 60.5 | I16: 60.5 | J16: 60.5 | K16: 60.5 | L16: 60.5
B17: Days Payable Outstanding (DPO) | C17: - | D17: - | E17: - | F17: - | G17: - | H17: 72.8 | I17: 72.8 | J17: 72.8 | K17: 72.8 | L17: 72.8
B19: CapEX | C19: - | D19: - | E19: - | F19: - | G19: - | H19: 12 | I19: 12 | J19: 12 | K19: 12 | L19: 12
B20: Rimborso Debito | C20: - | D20: - | E20: - | F20: - | G20: - | H20: -5 | I20: -5 | J20: -5 | K20: -5 | L20: 0
B21: Tasso interesse | C21: - | D21: - | E21: - | F21: - | G21: - | H21: 0.06 | I21: 0.06 | J21: 0.06 | K21: 0.06 | L21: 0.06
B22: Interessi su cassa | C22: - | D22: - | E22: - | F22: - | G22: - | H22: 0 | I22: 0 | J22: 0 | K22: 0 | L22: 0
B23: Dividendi | C23: - | D23: - | E23: - | F23: - | G23: - | H23: 0 | I23: 0 | J23: 0 | K23: 0 | L23: 0
B24: Aumenti di capitale | C24: - | D24: - | E24: - | F24: - | G24: - | H24: 0 | I24: 0 | J24: 0 | K24: 0 | L24: 0
A26: x | B26: Income statement
B28: Ricavi (Revenues) | C28: 100 | D28: 115 | E28: 130 | F28: 145 | G28: 160 | H28: =+G28*(1+H9) -> 176 | I28: =+H28*(1+I9) -> 191.84 | J28: =+I28*(1+J9) -> 207.1872 | K28: =+J28*(1+K9) -> 221.6903 | L28: =+K28*(1+L9) -> 234.99172
B29: Costo del Venduto (COGS) | C29: -30 | D29: -33.4 | E29: -36.4 | F29: -39.2 | G29: -41.6 | H29: =+H28*-H10 -> -45.76 | I29: =+I28*-I10 -> -49.8784 | J29: =+J28*-J10 -> -53.868672 | K29: =+K28*-K10 -> -57.639479 | L29: =+L28*-L10 -> -61.097848
B30: Utile Lordo (Gross Profit) | C30: =+C28+C29 -> 70 | D30: =+D28+D29 -> 81.6 | E30: =+E28+E29 -> 93.6 | F30: =+F28+F29 -> 105.8 | G30: =+G28+G29 -> 118.4 | H30: =+H28+H29 -> 130.24 | I30: =+I28+I29 -> 141.9616 | J30: =+J28+J29 -> 153.31853 | ... L30: =+L28+L29 -> 173.89387
B31: Spese Operative (SG&A) | C31: -40 | D31: -45 | E31: -50 | F31: -54 | G31: -58 | H31: =+H28*-H11 -> -61.6 | I31: =+I28*-I11 -> -66.1848 | J31: =+J28*-J11 -> -70.443648 | K31: =+K28*-K11 -> -75.374703 | L31: =+L28*-L11 -> -79.897186
B32: EBITDA | C32: =+C30+C31 -> 30 | D32: =+D30+D31 -> 36.6 | E32: =+E30+E31 -> 43.6 | F32: =+F30+F31 -> 51.8 | G32: =+G30+G31 -> 60.4 | H32: =+H30+H31 -> 68.64 | I32: =+I30+I31 -> 75.7768 | J32: =+J30+J31 -> 82.87488 | ... L32: =+L30+L31 -> 93.996689
B33: Ammortamenti (D&A) | C33: -5 | D33: -6 | E33: -7 | F33: -8 | G33: -9 | H33: =+H12*H70 -> -10.2 | I33: =+I12*I70 -> -10.2 | J33: =+J12*J70 -> -10.2 | K33: =+K12*K70 -> -10.2 | L33: =+L12*L70 -> -10.2
B34: EBIT (Operating Income) | C34: =+C32+C33 -> 25 | D34: =+D32+D33 -> 30.6 | E34: =+E32+E33 -> 36.6 | F34: =+F32+F33 -> 43.8 | G34: =+G32+G33 -> 51.4 | H34: =+H32+H33 -> 58.44 | I34: =+I32+I33 -> 65.5768 | J34: =+J32+J33 -> 72.67488 | ... L34: =+L32+L33 -> 83.796689
B35: Interessi Passivi | C35: -2 | D35: -2 | E35: -1.8 | F35: -1.5 | G35: -1.2 | H35: =+G51*-H21 -> -1.2 | I35: =+H51*-I21 -> -0.9 | J35: =+I51*-J21 -> -0.6 | K35: =+J51*-K21 -> -0.3 | L35: =+K51*-L21 -> 0
B36: Utile Ante Imposte (EBT) | C36: =+C34+C35 -> 23 | D36: =+D34+D35 -> 28.6 | E36: =+E34+E35 -> 34.8 | F36: =+F34+F35 -> 42.3 | G36: =+G34+G35 -> 50.2 | H36: =+H34+H35 -> 57.24 | I36: =+I34+I35 -> 64.6768 | J36: =+J34+J35 -> 72.07488 | ... L36: =+L34+L35 -> 83.796689 | P36: Year | Q36: 2021 | R36: 2022 | S36: =+R36+1 -> 2023 | T36: =+S36+1 -> 2024 | U36: =+T36+1 -> 2025 | V36: =+U36+1 -> 2026 | W36: =+V36+1 -> 2027 | X36: =+W36+1 -> 2028 | Y36: =+X36+1 -> 2029 | Z36: =+Y36+1 -> 2030
B37: Imposte | C37: -5.75 | D37: -7.15 | E37: -8.7 | F37: -10.58 | G37: -12.55 | H37: =+H36*-H13 -> -14.31 | I37: =+I36*-I13 -> -16.1692 | J37: =+J36*-J13 -> -18.01872 | K37: =+K36*-K13 -> -19.54403 | L37: =+L36*-L13 -> -20.949172 | P37: OCF | Q37: - | R37: =+D67 -> 26.05 | S37: =+E67 -> 31.7 | T37: =+F67 -> 38.32 | U37: =+G67 -> 45.25 | V37: =+H67 -> 51.672049 | W37: =+I67 -> 57.262384 | X37: =+J67 -> 62.855907 | Y37: =+K67 -> 67.508852 | Z37: =+L67 -> 71.833917
B38: Utile Netto (Net Income) | C38: =+C36+C37 -> 17.25 | D38: =+D36+D37 -> 21.45 | E38: =+E36+E37 -> 26.1 | F38: =+F36+F37 -> 31.72 | G38: =+G36+G37 -> 37.65 | H38: =+H36+H37 -> 42.93 | I38: =+I36+I37 -> 48.5076 | J38: =+J36+J37 -> 54.05616 | ... L38: =+L36+L37 -> 62.847517 | P38: ICF | Q38: - | R38: =+D71 -> -10 | S38: =+E71 -> -10 | T38: =+F71 -> -10 | U38: =+G71 -> -10 | V38: =+H71 -> -12 | W38: =+I71 -> -12 | X38: =+J71 -> -12 | Y38: =+K71 -> -12 | Z38: =+L71 -> -12
P39: FCF | Q39: - | R39: =+D76 -> -5 | S39: =+E76 -> -5 | T39: =+F76 -> -5 | U39: =+G76 -> -5 | V39: =+H76 -> -5 | W39: =+I76 -> -5 | X39: =+J76 -> -5 | Y39: =+K76 -> -5 | Z39: =+L76 -> 0
A40: x | B40: Balance Sheet Statement
B42: ATTIVO
B43: Cassa e Equivalenti | C43: 15 | D43: 26.05 | E43: 42.75 | F43: 66.07 | G43: 96.32 | H43: =+H81 -> 130.99205 | I43: =+I81 -> 171.25443 | J43: =+J81 -> 217.11034 | K43: =+K81 -> 267.61919 | L43: =+L81 -> 327.45311
B44: Crediti Commerciali (AR) | C44: 10 | D44: 11.5 | E44: 13 | F44: 14.5 | G44: 16 | H44: =+ABS(H28*H15)/365 -> 17.6 | I44: =+ABS(I28*I15)/365 -> 19.184 | J44: =+ABS(J28*J15)/365 -> 20.71872 | K44: =+ABS(K28*K15)/365 -> 22.16903 | L44: =+ABS(L28*L15)/365 -> 23.499172
B45: Magazzino (Inventory) | C45: 5 | D45: 5.6 | E45: 6.1 | F45: 6.5 | G45: 6.9 | H45: =+ABS(H29*H16)/365 -> 7.5848767 | I45: =+ABS(I29*I16)/365 -> 8.2675156 | J45: =+ABS(J29*J16)/365 -> 8.9289169 | K45: =+ABS(K29*K16)/365 -> 9.553941 | L45: =+ABS(L29*L16)/365 -> 10.127178
B46: Immobilizzazioni Nette (PP&E) | C46: 40 | D46: 44 | E46: 47 | F46: 49 | G46: 50 | H46: =+G46+$N$46+H33 -> 51.8 | I46: =+H46+$N$46+I33 -> 53.6 | J46: =+I46+$N$46+J33 -> 55.4 | K46: =+J46+$N$46+K33 -> 57.2 | L46: =+K46+$N$46+L33 -> 59 | M46: fixed CapEx | N46: 12
B47: TOTALE ATTIVO | C47: =SUM(C43:C46) -> 70 | D47: =SUM(D43:D46) -> 87.15 | E47: =SUM(E43:E46) -> 108.85 | F47: =SUM(F43:F46) -> 136.07 | G47: =SUM(G43:G46) -> 169.22 | H47: =SUM(H43:H46) -> 207.97693 | I47: =SUM(I43:I46) -> 252.30595 | J47: =SUM(J43:J46) -> 302.15798 | ... L47: =SUM(L43:L46) -> 420.07946
B49: PASSIVO E PATRIMONIO
B50: Debiti Commerciali (AP) | C50: 6 | D50: 6.7 | E50: 7.3 | F50: 7.8 | G50: 8.3 | H50: =+ABS(H29*H17)/365 -> 9.126926 | I50: =+ABS(I29*I17)/365 -> 9.9483494 | J50: =+ABS(J29*J17)/365 -> 10.744217 | K50: =+ABS(K29*K17)/365 -> 11.496313 | L50: =+ABS(L29*L17)/365 -> 12.186091
...

Sheet DCF_Model
B3: Voci (in mln) | C3: -1 | D3: =+C3+1 -> 0 | E3: =+D3+1 -> 1 | F3: =+E3+1 -> 2 | G3: =+F3+1 -> 3 | H3: =+G3+1 -> 4 | I3: =+H3+1 -> 5 | O3: x | P3: Data Visualitation
A4: x | B4: EBIT | C4: =+'3_Statements_Model'!F34 -> 43.8 | D4: =+'3_Statements_Model'!G34 -> 51.4 | E4: =+'3_Statements_Model'!H34 -> 58.44 | F4: =+'3_Statements_Model'!I34 -> 65.5768 | G4: =+'3_Statements_Model'!J34 -> 72.67488 | H4: =+'3_Statements_Model'!K34 -> 78.476122 | I4: =+'3_Statements_Model'!L34 -> 83.796689
B5: tax rate | C5: 0.25 | D5: 0.25 | E5: 0.25 | F5: 0.25 | G5: 0.25 | H5: 0.25 | I5: 0.25 | P5: Year | Q5: 0 | R5: =+Q5+1 -> 1 | S5: =+R5+1 -> 2 | T5: =+S5+1 -> 3 | U5: =+T5+1 -> 4 | V5: =+U5+1 -> 5
B6: NOPAT | C6: =+C4*(1-C5) -> 32.85 | D6: =+D4*(1-D5) -> 38.55 | E6: =+E4*(1-E5) -> 43.83 | F6: =+F4*(1-F5) -> 49.1826 | G6: =+G4*(1-G5) -> 54.50616 | H6: =+H4*(1-H5) -> 58.857091 | I6: =+I4*(1-I5) -> 62.847517 | P6: uDCF | Q6: =+D11 -> 36.15 | R6: =+E11 -> 35.412233 | S6: =+F11 -> 34.996047 | T6: =+G11 -> 34.115085 | U6: =+H11 -> 32.346293 | V6: =+I11 -> 30.309534
B7: (+) Ammortamenti (D&A) | C7: =-'3_Statements_Model'!F33 -> 8 | D7: =-'3_Statements_Model'!G33 -> 9 | E7: =-'3_Statements_Model'!H33 -> 10.2 | F7: =-'3_Statements_Model'!I33 -> 10.2 | G7: =-'3_Statements_Model'!J33 -> 10.2 | H7: =-'3_Statements_Model'!K33 -> 10.2 | I7: =-'3_Statements_Model'!L33 -> 10.2 | P7: PFN | Q7: =+'3_Statements_Model'!G51-'3_Statements_Model'!G43 -> -76.32 | R7: =+'3_Statements_Model'!H51-'3_Statements_Model'!H43 -> -115.99205 | S7: =+'3_Statements_Model'!I51-'3_Statements_Model'!I43 -> -161.25443 | T7: =+'3_Statements_Model'!J51-'3_Statements_Model'!J43 -> -212.11034 | U7: =+'3_Statements_Model'!K51-'3_Statements_Model'!K43 -> -267.61919 | V7: =+'3_Statements_Model'!L51-'3_Statements_Model'!L43 -> -327.45311
B8: (+/-) CCN | C8: =+'3_Statements_Model'!F66 -> -1.4 | D8: =+'3_Statements_Model'!G66 -> -1.4 | E8: =+'3_Statements_Model'!H66 -> -1.4579507 | F8: =+'3_Statements_Model'!I66 -> -1.4452156 | G8: =+'3_Statements_Model'!J66 -> -1.4002533 | H8: =+'3_Statements_Model'!K66 -> -1.3232394 | I8: =+'3_Statements_Model'!L66 -> -1.2135995
B9: (-) CapEx | C9: =+'3_Statements_Model'!F70 -> -10 | D9: =+'3_Statements_Model'!G70 -> -10 | E9: =+'3_Statements_Model'!H70 -> -12 | F9: =+'3_Statements_Model'!I70 -> -12 | G9: =+'3_Statements_Model'!J70 -> -12 | H9: =+'3_Statements_Model'!K70 -> -12 | I9: =+'3_Statements_Model'!L70 -> -12
B10: uFCFF | C10: =SUM(C6:C9) -> 29.45 | D10: =SUM(D6:D9) -> 36.15 | E10: =SUM(E6:E9) -> 40.572049 | F10: =SUM(F6:F9) -> 45.937384 | G10: =SUM(G6:G9) -> 51.305907 | H10: =SUM(H6:H9) -> 55.733852 | I10: =SUM(I6:I9) -> 59.833917
B11: uDCF | D11: =+D10/(1+$C$32)^(D3) -> 36.15 | E11: =+E10/(1+$C$32)^(E3) -> 35.412233 | F11: =+F10/(1+$C$32)^(F3) -> 34.996047 | G11: =+G10/(1+$C$32)^(G3) -> 34.115085 | H11: =+H10/(1+$C$32)^(H3) -> 32.346293 | I11: =+I10/(1+$C$32)^(I3) -> 30.309534
B13: Undiscounted Cash Flow
B14: uDCF | D14: =+D11 -> 36.15 | E14: =+E11 -> 35.412233 | F14: =+F11 -> 34.996047 | G14: =+G11 -> 34.115085 | H14: =+H11 -> 32.346293 | I14: =+I11 -> 30.309534 | K14: growth rate
B15: Terminal Value | I15: =+(I10*(1+K15))/(C32-K15) -> 485.49807 | K15: 0.02
B17: EV | F17: EqV
B18: NPV CF | D18: =+SUM(E14:I14) -> 167.17919 | F18: (+) EV | H18: =+D20 -> 413.11362
B19: NPV TV | D19: =+I15/(1+C32)^I3 -> 245.93443 | F19: (-) PFN | H19: =D26 -> -76.32
B20: Enterprise Value | D20: =SUM(D18:D19) -> 413.11362 | F20: Equity Value | H20: =+H18-H19 -> 489.43362
B23: PFN | F23: EVpS | J23: Buy-Sell | K23: =+IF(K24>K25,"Compra","Vendi") -> Compra
B24: (+) Financial debt | D24: =+'3_Statements_Model'!G51 -> 20 | F24: (+) EqV | H24: =+H20*1000000 -> 4.8943362e+08 | J24: EqV | K24: =+H26 -> 48.943362
B25: (-) Liquidità | D25: =-'3_Statements_Model'!G43 -> -96.32 | F25: DSO | H25: 10000000 | J25: Book Value | K25: =+('3_Statements_Model'!G56*1000000)/H25 -> 14.092
B26: PFN | D26: =+D24+D25 -> -76.32 | F26: Equity Value per Share | H26: =+H24/H25 -> 48.943362
A29: x | B29: Metrics
A31: x | B31: WACC
B32: WACC | C32: =+D33*C36+D34*E36 -> 0.14570718
B33: E | C33: =+'3_Statements_Model'!G56 -> 140.92 | D33: =+C33/$C$35 -> 0.87571464
B34: D | C34: =+'3_Statements_Model'!G51 -> 20 | D34: =+C34/$C$35 -> 0.12428536
B35: tot | C35: =SUM(C33:C34) -> 160.92 | D35: =SUM(D33:D34) -> 1
B36: ke | C36: =+C37+C38*(C39-C37) -> 0.16 | D36: kd | E36: =+'3_Statements_Model'!H21*(1-'3_Statements_Model'!H13) -> 0.045
B37: rf | C37: 0.02
B38: B | C38: 1.4
B39: rm | C39: 0.12

Sheet Assumptions
A2: x | B2: Conto Economico
B4: Revenue Growth Rate: 10% nel 2026, per poi decrescere linearmente di 1 punto percentuale all'anno (9% nel 2027, 8% nel 2028, 7% nel 2029, 6% nel 2030).
B6: COGS (% of Revenues): Rimane stabile al 26,0% dei ricavi per tutti i 5 anni.
B8: SG&A (% of Revenues): Efficienza operativa in miglioramento. Impostalo al 35,0% nel 2026, 34,5% nel 2027, e fisso al 34,0% dal 2028 al 2030.
B10: D&A (% of Capital Expenditures): Storicamente gli ammortamenti seguono il CapEx. Imposta la D&A pari all'85% del CapEx di ciascun anno corrente.
B12: Tax Rate: Costante al 25% sull'EBT.
A14: x | B14: Capitale Circolante Netto (Working Capital Drivers)
B16: Days Sales Outstanding (DSO): Calcolato su base storica 2025 (circa 36,5 giorni). Mantieni 36,5 giorni fissi
B18: Days Inventory Outstanding (DIO): Mantieni 60,5 giorni fissi
B20: Days Payable Outstanding (DPO): Mantieni 72,8 giorni fissi
A22: x | B22: Stato Patrimoniale e Flussi Finanziari (CapEx & Debito)
B24: Capital Expenditures (CapEx): L'azienda deve supportare la crescita. Imposta il CapEx fisso a 12,0 milioni di € all'anno dal 2026 al 2030.
B26: Rimborso Debito (Debt Paydown): L'azienda continua a rimborsare 5,0 milioni di € all'anno di debito esistente fino all'azzeramento dello stesso.
B28: Tasso di Interesse sul Debito: Fissato al 6,0% calcolato sul Debito Iniziale (Beginning Debt) di ciascun anno.
B30: Interessi attivi sulla Cassa: Per semplicità, assumere 0% (la cassa non genera interessi).
B32: Dividendi / Aumenti di Capitale: Assumere 0 per entrambi (tutto l'utile va a riserva).
A34: x | B34: DCF: key variables
B36: Tasso risk free (rf): 2%
B38: growth rate (g): 2%
B40: Market return (rm): 12%
B42: Diluted Shares Outstanding (DSO): 10 mln

Sheet Raw_data
B2: CE
B3: Voce (€ milioni) | C3: 2021 | D3: 2022 | E3: 2023 | F3: 2024 | G3: 2025
B4: Ricavi (Revenues) | C4: 100,00 | D4: 115,00 | E4: 130,00 | F4: 145,00 | G4: 160,00
B5: Costo del Venduto (COGS) | C5: -30,00 | D5: -33,40 | E5: -36,40 | F5: -39,20 | G5: -41,60
B6: Utile Lordo (Gross Profit) | C6: 70,00 | D6: 81,60 | E6: 93,60 | F6: 105,80 | G6: 118,40
B7: Spese Operative (SG&A) | C7: -40,00 | D7: -45,00 | E7: -50,00 | F7: -54,00 | G7: -58,00
B8: EBITDA | C8: 30,00 | D8: 36,60 | E8: 43,60 | F8: 51,80 | G8: 60,40
B9: Ammortamenti (D&A) | C9: -5,00 | D9: -6,00 | E9: -7,00 | F9: -8,00 | G9: -9,00
B10: EBIT (Operating Income) | C10: 25,00 | D10: 30,60 | E10: 36,60 | F10: 43,80 | G10: 51,40
B11: Interessi Passivi | C11: -2,00 | D11: -2,00 | E11: -1,80 | F11: -1,50 | G11: -1,20
B12: Utile Ante Imposte (EBT) | C12: 23,00 | D12: 28,60 | E12: 34,80 | F12: 42,30 | G12: 50,20
B13: Imposte | C13: -5,75 | D13: -7,15 | E13: -8,70 | F13: -10,58 | G13: -12,55
B14: Utile Netto (Net Income) | C14: 17,25 | D14: 21,45 | E14: 26,10 | F14: 31,72 | G14: 37,65
B16: SP
B17: Voce (€ milioni) | C17: 2021 | D17: 2022 | E17: 2023 | F17: 2024 | G17: 2025
B18: ATTIVO
B19: Cassa e Equivalenti | C19: 15,00 | D19: 26,05 | E19: 42,75 | F19: 66,07 | G19: 96,32
B20: Crediti Commerciali (AR) | C20: 10,00 | D20: 11,50 | E20: 13,00 | F20: 14,50 | G20: 16,00
B21: Magazzino (Inventory) | C21: 5,00 | D21: 5,60 | E21: 6,10 | F21: 6,50 | G21: 6,90
B22: Immobilizzazioni Nette (PP&E) | C22: 40,00 | D22: 44,00 | E22: 47,00 | F22: 49,00 | G22: 50,00
B23: TOTALE ATTIVO | C23: 70,00 | D23: 87,15 | E23: 108,85 | F23: 136,07 | G23: 169,22
B25: PASSIVO E PATRIMONIO
B26: Debiti Commerciali (AP) | C26: 6,00 | D26: 6,70 | E26: 7,30 | F26: 7,80 | G26: 8,30
B27: Debito Finanziario (Senior Debt) | C27: 40,00 | D27: 35,00 | E27: 30,00 | F27: 25,00 | G27: 20,00
B28: Totale Passività | C28: 46,00 | D28: 41,70 | E28: 37,30 | F28: 32,80 | G28: 28,30
B29: Capitale Sociale | C29: 10,00 | D29: 10,00 | E29: 10,00 | F29: 10,00 | G29: 10,00
B30: Riserve / Utili Portati a Nuovo | C30: 14,00 | D30: 35,45 | E30: 61,55 | F30: 93,27 | G30: 130,92
B31: Totale Patrimonio Netto | C31: 24,00 | D31: 45,45 | E31: 71,55 | F31: 103,27 | G31: 140,92
B32: TOTALE PASSIVO E PATRIMONIO | C32: 70,00 | D32: 87,15 | E32: 108,85 | F32: 136,07 | G32: 169,22
B33: CHECK (Attivo - Passivo - PN) | C33: 0,00 | D33: 0,00 | E33: 0,00 | F33: 0,00 | G33: 0,00
B35: Voce (€ milioni) | C35: 2022 | D35: 2023 | E35: 2024 | F35: 2025
B36: Utile Netto | C36: 21,45 | D36: 26,10 | E36: 31,72 | F36: 37,65
B37: (+) Ammortamenti (D&A) | C37: 6,00 | D37: 7,00 | E37: 8,00 | F37: 9,00
B38: (-/+) Variazione Crediti (AR) | C38: -1,50 | D38: -1,50 | E38: -1,50 | F38: -1,50
B39: (-/+) Variazione Magazzino | C39: -0,60 | D39: -0,50 | E39: -0,40 | F39: -0.4
B40: (+/-) Variazione Debiti (AP) | C40: 0,70 | D40: 0,60 | E40: 0,50 | F40: 0,50
B41: Flusso di Cassa Operativo (CFO) | C41: 26,05 | D41: 31,70 | E41: 38,32 | F41: 45,25
B42: Spese in conto capitale (CapEx) | C42: -10,00 | D42: -10,00 | E42: -10,00 | F42: -10,00
B43: Flusso di Cassa da Investimenti (CFI) | C43: -10,00 | D43: -10,00 | E43: -10,00 | F43: -10,00
B44: Rimborso Debito | C44: -5,00 | D44: -5,00 | E44: -5,00 | F44: -5,00
...
